Workbook

Sheet Excel_jumia_dataset (1)
A1: Product | B1: Current price | C1: old price | D1: Discount | E1: Review | F1: Rating | G1: Absolute Discount | H1: Rating Category | I1: Discount % Category
A2: Classic Black Cat Cotton Hemp Pillow Case For Home Car | B2: 171 | C2: 360 | D2: 0.53 | E2: 2 | F2: 5 | G2: =C2-B2 -> 189 | H2: =IF(F2="","",IF(F2<3,"Poor",IF(F2>=4.5,"Excellent","Average"))) -> Excellent | I2: =IF(D2="","",IF(D2<20%,"Low Discount",IF(D2<=40%,"Medium Discount","High Discount"))) -> High Discount
A3: Anti-Skid Absorbent Insulation Coaster For Home Office | B3: 332 | C3: 684 | D3: 0.51 | E3: 2 | F3: 5 | G3: =C3-B3 -> 352 | H3: =IF(F3="","",IF(F3<3,"Poor",IF(F3>=4.5,"Excellent","Average"))) -> Excellent | I3: =IF(D3="","",IF(D3<20%,"Low Discount",IF(D3<=40%,"Medium Discount","High Discount"))) -> High Discount
A4: LASA Aluminum Folding Truck Hand Cart - 68kg Max | B4: 2025 | C4: 3971 | D4: 0.49 | E4: 3 | F4: 5 | G4: =C4-B4 -> 1946 | H4: =IF(F4="","",IF(F4<3,"Poor",IF(F4>=4.5,"Excellent","Average"))) -> Excellent | I4: =IF(D4="","",IF(D4<20%,"Low Discount",IF(D4<=40%,"Medium Discount","High Discount"))) -> High Discount
A5: Bedroom Simple Floor Hanging Clothes Rack Single Pole Hat Rack - White | B5: 979 | C5: 1920 | D5: 0.49 | E5: 1 | F5: 5 | G5: =C5-B5 -> 941 | H5: =IF(F5="","",IF(F5<3,"Poor",IF(F5>=4.5,"Excellent","Average"))) -> Excellent | I5: =IF(D5="","",IF(D5<20%,"Low Discount",IF(D5<=40%,"Medium Discount","High Discount"))) -> High Discount
A6: Peacock Throw Pillow Cushion Case For Home Car | B6: 195 | C6: 360 | D6: 0.46 | E6: 2 | F6: 5 | G6: =C6-B6 -> 165 | H6: =IF(F6="","",IF(F6<3,"Poor",IF(F6>=4.5,"Excellent","Average"))) -> Excellent | I6: =IF(D6="","",IF(D6<20%,"Low Discount",IF(D6<=40%,"Medium Discount","High Discount"))) -> High Discount
A7: DIY File Folder Office Drawer File Holder Pen Holder Desktop Storage Rack | B7: 1620 | C7: 2690 | D7: 0.4 | E7: 1 | F7: 5 | G7: =C7-B7 -> 1070 | H7: =IF(F7="","",IF(F7<3,"Poor",IF(F7>=4.5,"Excellent","Average"))) -> Excellent | I7: =IF(D7="","",IF(D7<20%,"Low Discount",IF(D7<=40%,"Medium Discount","High Discount"))) -> Medium Discount
A8: Konka Healty Electric Kettle 24-hour Heat Preservation1.5L800W White | B8: 3640 | C8: 4588 | D8: 0.21 | E8: 1 | F8: 5 | G8: =C8-B8 -> 948 | H8: =IF(F8="","",IF(F8<3,"Poor",IF(F8>=4.5,"Excellent","Average"))) -> Excellent | I8: =IF(D8="","",IF(D8<20%,"Low Discount",IF(D8<=40%,"Medium Discount","High Discount"))) -> Medium Discount
A9: LASA FOLDING TABLE SERVING STAND | B9: 1274 | C9: 2800 | D9: 0.55 | E9: 5 | F9: 4.8 | G9: =C9-B9 -> 1526 | H9: =IF(F9="","",IF(F9<3,"Poor",IF(F9>=4.5,"Excellent","Average"))) -> Excellent | I9: =IF(D9="","",IF(D9<20%,"Low Discount",IF(D9<=40%,"Medium Discount","High Discount"))) -> High Discount
A10: 40cm Gold DIY Acrylic Wall Sticker Clock | B10: 552 | C10: 1035 | D10: 0.47 | E10: 12 | F10: 4.8 | G10: =C10-B10 -> 483 | H10: =IF(F10="","",IF(F10<3,"Poor",IF(F10>=4.5,"Excellent","Average"))) -> Excellent | I10: =IF(D10="","",IF(D10<20%,"Low Discount",IF(D10<=40%,"Medium Discount","High Discount"))) -> High Discount
A11: Portable Home Small Air Humidifier 3-Speed Fan - Green | B11: 1740 | C11: 2356 | D11: 0.26 | E11: 5 | F11: 4.8 | G11: =C11-B11 -> 616 | H11: =IF(F11="","",IF(F11<3,"Poor",IF(F11>=4.5,"Excellent","Average"))) -> Excellent | I11: =IF(D11="","",IF(D11<20%,"Low Discount",IF(D11<=40%,"Medium Discount","High Discount"))) -> Medium Discount
A12: Weighing Scale Digital Bathroom Body Fat Scale USB-Black | B12: 1580 | C12: 2499 | D12: 0.37 | E12: 7 | F12: 4.7 | G12: =C12-B12 -> 919 | H12: =IF(F12="","",IF(F12<3,"Poor",IF(F12>=4.5,"Excellent","Average"))) -> Excellent | I12: =IF(D12="","",IF(D12<20%,"Low Discount",IF(D12<=40%,"Medium Discount","High Discount"))) -> Medium Discount
A13: 100 Pcs Crochet Hook Tool Set Knitting Hook Set With Box | B13: 990 | C13: 1500 | D13: 0.34 | E13: 39 | F13: 4.7 | G13: =C13-B13 -> 510 | H13: =IF(F13="","",IF(F13<3,"Poor",IF(F13>=4.5,"Excellent","Average"))) -> Excellent | I13: =IF(D13="","",IF(D13<20%,"Low Discount",IF(D13<=40%,"Medium Discount","High Discount"))) -> Medium Discount
... A22: 115 Piece Set Of Multifunctional Precision Screwdrivers | B22: 950 | C22: 1525 | D22: 0.38 | E22: 2 | F22: 4.5 | G22: =C22-B22 -> 575 | H22: =IF(F22="","",IF(F22<3,"Poor",IF(F22>=4.5,"Excellent","Average"))) -> Excellent | I22: =IF(D22="","",IF(D22<20%,"Low Discount",IF(D22<=40%,"Medium Discount","High Discount"))) -> Medium Discount
A23: 1/2/3 Seater Elastic Sofa CoverLiving Room/Home Decor Chair Cover-Grey | B23: 1620 - 1980 | C23: 2200 - 3200 | D23: 0.38 | E23: 2 | F23: 4.5 | G23: =C23-B23 -> #VALUE! | H23: =IF(F23="","",IF(F23<3,"Poor",IF(F23>=4.5,"Excellent","Average"))) -> Excellent | I23: =IF(D23="","",IF(D23<20%,"Low Discount",IF(D23<=40%,"Medium Discount","High Discount"))) -> Medium Discount
A24: 53 Pieces/Set Yarn Knitting Crochet Hooks With Bag - Pansies | B24: 1980 | C24: 2699 | D24: 0.27 | E24: 32 | F24: 4.5 | G24: =C24-B24 -> 719 | H24: =IF(F24="","",IF(F24<3,"Poor",IF(F24>=4.5,"Excellent","Average"))) -> Excellent | I24: =IF(D24="","",IF(D24<20%,"Low Discount",IF(D24<=40%,"Medium Discount","High Discount"))) -> Medium Discount
A25: Foldable Overbed Table/Desk | B25: 1650 | C25: 2150 | D25: 0.23 | E25: 14 | F25: 4.4 | G25: =C25-B25 -> 500 | H25: =IF(F25="","",IF(F25<3,"Poor",IF(F25>=4.5,"Excellent","Average"))) -> Average | I25: =IF(D25="","",IF(D25<20%,"Low Discount",IF(D25<=40%,"Medium Discount","High Discount"))) -> Medium Discount
A26: LASA 3 Tier Bamboo Shoe Bench Storage Shelf | B26: 2048 | C26: 4500 | D26: 0.54 | E26: 7 | F26: 4.3 | G26: =C26-B26 -> 2452 | H26: =IF(F26="","",IF(F26<3,"Poor",IF(F26>=4.5,"Excellent","Average"))) -> Average | I26: =IF(D26="","",IF(D26<20%,"Low Discount",IF(D26<=40%,"Medium Discount","High Discount"))) -> High Discount
A27: Exfoliate And Exfoliate Face Towel - Black | B27: 185 | C27: 382 | D27: 0.52 | E27: 9 | F27: 4.3 | G27: =C27-B27 -> 197 | H27: =IF(F27="","",IF(F27<3,"Poor",IF(F27>=4.5,"Excellent","Average"))) -> Average | I27: =IF(D27="","",IF(D27<20%,"Low Discount",IF(D27<=40%,"Medium Discount","High Discount"))) -> High Discount
A28: LED Eye Protection Desk Lamp Study Reading USB Fan - Double Pen Holder | B28: 1820 | C28: 3490 | D28: 0.48 | E28: 9 | F28: 4.3 | G28: =C28-B28 -> 1670 | H28: =IF(F28="","",IF(F28<3,"Poor",IF(F28>=4.5,"Excellent","Average"))) -> Average | I28: =IF(D28="","",IF(D28<20%,"Low Discount",IF(D28<=40%,"Medium Discount","High Discount"))) -> High Discount
A29: Punch-free Great Load Bearing Bathroom Storage Rack Wall Shelf-White | B29: 389 | C29: 656 | D29: 0.41 | E29: 36 | F29: 4.3 | G29: =C29-B29 -> 267 | H29: =IF(F29="","",IF(F29<3,"Poor",IF(F29>=4.5,"Excellent","Average"))) -> Average | I29: =IF(D29="","",IF(D29<20%,"Low Discount",IF(D29<=40%,"Medium Discount","High Discount"))) -> High Discount
A30: Multifunction Laser Level With Adjustment Tripod | B30: 1680 | C30: 2499 | D30: 0.33 | E30: 9 | F30: 4.2 | G30: =C30-B30 -> 819 | H30: =IF(F30="","",IF(F30<3,"Poor",IF(F30>=4.5,"Excellent","Average"))) -> Average | I30: =IF(D30="","",IF(D30<20%,"Low Discount",IF(D30<=40%,"Medium Discount","High Discount"))) -> Medium Discount
A31: Metal Decorative Hooks Key Hangers Entryway Wall Hooks Towel Hooks - Home | B31: 527 | C31: 999 | D31: 0.47 | E31: 14 | F31: 4.1 | G31: =C31-B31 -> 472 | H31: =IF(F31="","",IF(F31<3,"Poor",IF(F31>=4.5,"Excellent","Average"))) -> Average | I31: =IF(D31="","",IF(D31<20%,"Low Discount",IF(D31<=40%,"Medium Discount","High Discount"))) -> High Discount
A32: 52 Pieces Cake Decorating Tool Set Gift Kit Baking Supplies | B32: 1758 | C32: 2499 | D32: 0.3 | E32: 20 | F32: 4.1 | G32: =C32-B32 -> 741 | H32: =IF(F32="","",IF(F32<3,"Poor",IF(F32>=4.5,"Excellent","Average"))) -> Average | I32: =IF(D32="","",IF(D32<20%,"Low Discount",IF(D32<=40%,"Medium Discount","High Discount"))) -> Medium Discount
A33: Genebre 115 In 1 Screwdriver Repairing Tool Set For IPhone Cellphone Hand Tool | B33: 799 | C33: 999 | D33: 0.2 | E33: 12 | F33: 4.1 | G33: =C33-B33 -> 200 | H33: =IF(F33="","",IF(F33<3,"Poor",IF(F33>=4.5,"Excellent","Average"))) -> Average | I33: =IF(D33="","",IF(D33<20%,"Low Discount",IF(D33<=40%,"Medium Discount","High Discount"))) -> Medium Discount
A34: Household Pineapple Peeler Peeler | B34: 330 | C34: 647 | D34: 0.49 | E34: 1 | F34: 4 | G34: =C34-B34 -> 317 | H34: =IF(F34="","",IF(F34<3,"Poor",IF(F34>=4.5,"Excellent","Average"))) -> Average | I34: =IF(D34="","",IF(D34<20%,"Low Discount",IF(D34<=40%,"Medium Discount","High Discount"))) -> High Discount
A35: Desk Foldable Fan Adjustable Fan Strong Wind 3 Gear Usb | B35: 988 | C35: 1580 | D35: 0.37 | E35: 2 | F35: 4 | G35: =C35-B35 -> 592 | H35: =IF(F35="","",IF(F35<3,"Poor",IF(F35>=4.5,"Excellent","Average"))) -> Average | I35: =IF(D35="","",IF(D35<20%,"Low Discount",IF(D35<=40%,"Medium Discount","High Discount"))) -> Medium Discount
... A58: Wall-mounted Sticker Punch-free Plug Fixer | B58: 450 | C58: 900 | D58: 0.5 | E58: 1 | F58: 2 | G58: =C58-B58 -> 450 | H58: =IF(F58="","",IF(F58<3,"Poor",IF(F58>=4.5,"Excellent","Average"))) -> Poor | I58: =IF(D58="","",IF(D58<20%,"Low Discount",IF(D58<=40%,"Medium Discount","High Discount"))) -> High Discount
A59: 6 In 1 Bottle Can Opener Multifunctional Easy Opener | B59: 199 | C59: 553 | D59: 0.64 | G59: =C59-B59 -> 354 | H59: =IF(F59="","",IF(F59<3,"Poor",IF(F59>=4.5,"Excellent","Average"))) | I59: =IF(D59="","",IF(D59<20%,"Low Discount",IF(D59<=40%,"Medium Discount","High Discount"))) -> High Discount
A60: Creative Owl Shape Keychain Black | B60: 199 | C60: 504 | D60: 0.61 | G60: =C60-B60 -> 305 | H60: =IF(F60="","",IF(F60<3,"Poor",IF(F60>=4.5,"Excellent","Average"))) | I60: =IF(D60="","",IF(D60<20%,"Low Discount",IF(D60<=40%,"Medium Discount","High Discount"))) -> High Discount
A61: Modern Sofa Throw Pillow Cover-45x45cm-Blue&Red | B61: 238 | C61: 476 | D61: 0.5 | G61: =C61-B61 -> 238 | H61: =IF(F61="","",IF(F61<3,"Poor",IF(F61>=4.5,"Excellent","Average"))) | I61: =IF(D61="","",IF(D61<20%,"Low Discount",IF(D61<=40%,"Medium Discount","High Discount"))) -> High Discount
A62: Christmas Elk Fence Yard Lawn Decorations Cute For Holidays | B62: 999 | C62: 2000 | D62: 0.5 | G62: =C62-B62 -> 1001 | H62: =IF(F62="","",IF(F62<3,"Poor",IF(F62>=4.5,"Excellent","Average"))) | I62: =IF(D62="","",IF(D62<20%,"Low Discount",IF(D62<=40%,"Medium Discount","High Discount"))) -> High Discount
A63: Brush & Paintbrush Cleaning Tool Pink | B63: 299 | C63: 600 | D63: 0.5 | G63: =C63-B63 -> 301 | H63: =IF(F63="","",IF(F63<3,"Poor",IF(F63>=4.5,"Excellent","Average"))) | I63: =IF(D63="","",IF(D63<20%,"Low Discount",IF(D63<=40%,"Medium Discount","High Discount"))) -> High Discount
A64: Wall Clock With Hidden Safe Box | B64: 850 | C64: 1700 | D64: 0.5 | G64: =C64-B64 -> 850 | H64: =IF(F64="","",IF(F64<3,"Poor",IF(F64>=4.5,"Excellent","Average"))) | I64: =IF(D64="","",IF(D64<20%,"Low Discount",IF(D64<=40%,"Medium Discount","High Discount"))) -> High Discount
A65: 2PCS Ice Silk Square Cushion Cover Pillowcases - 65x65cm | B65: 1200 | C65: 2400 | D65: 0.5 | G65: =C65-B65 -> 1200 | H65: =IF(F65="","",IF(F65<3,"Poor",IF(F65>=4.5,"Excellent","Average"))) | I65: =IF(D65="","",IF(D65<20%,"Low Discount",IF(D65<=40%,"Medium Discount","High Discount"))) -> High Discount
A66: 4M Float Switch Water Level Controller -Water Tank | B66: 475 | C66: 931 | D66: 0.49 | G66: =C66-B66 -> 456 | H66: =IF(F66="","",IF(F66<3,"Poor",IF(F66>=4.5,"Excellent","Average"))) | I66: =IF(D66="","",IF(D66<20%,"Low Discount",IF(D66<=40%,"Medium Discount","High Discount"))) -> High Discount
A67: Car Phone Charging Stand | B67: 671 | C67: 1316 | D67: 0.49 | G67: =C67-B67 -> 645 | H67: =IF(F67="","",IF(F67<3,"Poor",IF(F67>=4.5,"Excellent","Average"))) | I67: =IF(D67="","",IF(D67<20%,"Low Discount",IF(D67<=40%,"Medium Discount","High Discount"))) -> High Discount
A68: Angle Measuring Tool Full Metal Multi Angle Measuring Tool | B68: 799 | C68: 1567 | D68: 0.49 | G68: =C68-B68 -> 768 | H68: =IF(F68="","",IF(F68<3,"Poor",IF(F68>=4.5,"Excellent","Average"))) | I68: =IF(D68="","",IF(D68<20%,"Low Discount",IF(D68<=40%,"Medium Discount","High Discount"))) -> High Discount
A69: 7PCS Silicone Thumb Knife Finger Protector Vegetable Harvesting Knife | B69: 230 | C69: 450 | D69: 0.49 | G69: =C69-B69 -> 220 | H69: =IF(F69="","",IF(F69<3,"Poor",IF(F69>=4.5,"Excellent","Average"))) | I69: =IF(D69="","",IF(D69<20%,"Low Discount",IF(D69<=40%,"Medium Discount","High Discount"))) -> High Discount
A70: Cartoon Car Decoration Cute Individuality For Car Home Desk | B70: 274 | C70: 537 | D70: 0.49 | G70: =C70-B70 -> 263 | H70: =IF(F70="","",IF(F70<3,"Poor",IF(F70>=4.5,"Excellent","Average"))) | I70: =IF(D70="","",IF(D70<20%,"Low Discount",IF(D70<=40%,"Medium Discount","High Discount"))) -> High Discount
...

Sheet Dashboard
A1: PRODUCT PERFORMANCE DASHBOARD
A2: Interactive Analytics | E-commerce Insights
A3: TOTAL PRODUCTS | D3: AVERAGE RATINGS | G3: AVERAGE DISCOUNTS | J3: TOTAL REVIEWS
A4: =Pivots!A4 -> 109 | D4: =Pivots!A8 -> 3.8894737 | G4: =Pivots!A12 -> 0.36385321 | J4: =Pivots!A15 -> -723
A5: Excellent | D5: Average | G5: Poor | J5: With Reviews
A6: =Pivots!E5 -> 23 | D6: =Pivots!E4 -> 22 | G6: =Pivots!E6 -> 12 | J6: =Pivots!D12 -> 57
D10: PRODUCT PERFORMANCE TO 10 BY REVIEW
D11: No | E11: Product | F11: Discount | G11: Review | H11: Rating
D12: 1 | E12: 120W Cordless Vacuum Cleaners Handheld Electric Vacuum Cleaner | F12: 0.49 | G12: 69 | H12: 2.8
D13: 2 | E13: 137 Pieces Cake Decorating Tool Set Baking Supplies | F13: 0.24 | G13: 55 | H13: 4.6
D14: 3 | E14: Electronic Digital Display Vernier Caliper | F14: 0.35 | G14: 49 | H14: 4.6
D15: 4 | E15: 3D Waterproof EVA Plastic Shower Curtain 1.8*2Mtrs | F15: 0.49 | G15: 44 | H15: 4.6
D16: 5 | E16: 100 Pcs Crochet Hook Tool Set Knitting Hook Set With Box | F16: 0.34 | G16: 39 | H16: 4.7
D17: 6 | E17: Punch-free Great Load Bearing Bathroom Storage Rack Wall Shelf-White | F17: 0.41 | G17: 36 | H17: 4.3
D18: 7 | E18: 53 Pieces/Set Yarn Knitting Crochet Hooks With Bag - Pansies | F18: 0.27 | G18: 32 | H18: 4.5
D19: 8 | E19: Portable Mini Cordless Car Vacuum Cleaner - Blue | F19: 0.25 | G19: 24 | H19: 4.6
D20: 9 | E20: 52 Pieces Cake Decorating Tool Set Gift Kit Baking Supplies | F20: 0.3 | G20: 20 | H20: 4.1
D21: 10 | E21: 53Pcs/Set Yarn Knitting Crochet Hooks With Bag - Fortune Cat | F21: 0.27 | G21: 20 | H21: 4.7
A24: TREND ANALYSIS AND CATEGORY BREAKDOWN | I24: RATING CATEGORY DISTRIBUTION
A42: %DISCOUNTS VS REVIEWS | I42: RATINGS VS REVIEWS
A61: DISCOUNT CATEGORY DISTRIBUTION | I61: TOP 10 PRODUCTS BY DISCOUNT
A80: TOP 10 PRODUCTS BY RATING
A81: No | B81: Product | C81: Review | D81: Rating
A82: 1 | B82: Classic Black Cat Cotton Hemp Pillow Case For Home Car | C82: 2 | D82: 5
A83: 2 | B83: Anti-Skid Absorbent Insulation Coaster For Home Office | C83: 2 | D83: 5
A84: 3 | B84: LASA Aluminum Folding Truck Hand Cart - 68kg Max | C84: 3 | D84: 5
A85: 4 | B85: Bedroom Simple Floor Hanging Clothes Rack Single Pole Hat Rack - White | C85: 1 | D85: 5
A86: 5 | B86: Peacock Throw Pillow Cushion Case For Home Car | C86: 2 | D86: 5
A87: 6 | B87: DIY File Folder Office Drawer File Holder Pen Holder Desktop Storage Rack | C87: 1 | D87: 5
A88: 7 | B88: Konka Healty Electric Kettle 24-hour Heat Preservation1.5L800W White | C88: 1 | D88: 5
A89: 8 | B89: LASA FOLDING TABLE SERVING STAND | C89: 5 | D89: 4.8
A90: 9 | B90: 40cm Gold DIY Acrylic Wall Sticker Clock | C90: 12 | D90: 4.8
A91: 10 | B91: Portable Home Small Air Humidifier 3-Speed Fan - Green | C91: 5 | D91: 4.8

Sheet Pivots
A2: Total Number of Product | D2: Row Labels | E2: Count of Rating Category | G2: Row Labels | H2: Count of Discount % Category
A3: Count of Product | E3: 52 | G3: High Discount | H3: 59
A4: 109 | D4: Average | E4: 22 | G4: Low Discount | H4: 18
D5: Excellent | E5: 23 | G5: Medium Discount | H5: 32
D6: Poor | E6: 12 | G6: Grand Total | H6: 109
A7: Average of Ratingd | D7: Grand Total | E7: 109
A8: 3.8894737
D9: 22
D10: 23
A11: Average of Discount | D11: 12
A12: 0.36385321 | D12: =SUM(D9:D11) -> 57
A14: Sum of Review
A15: -723
A17: Product | B17: Current price | C17: old price | D17: Discount | E17: Review | F17: Rating | G17: Absolute Discount | H17: Rating Category | I17: Discount % Category
A18: 6 In 1 Bottle Can Opener Multifunctional Easy Opener | B18: 199 | C18: 553 | D18: 0.64 | G18: =C18-B18 -> 354 | H18: =IF(F18="","",IF(F18<3,"Poor",IF(F18>=4.5,"Excellent","Average"))) | I18: =IF(D18="","",IF(D18<20%,"Low Discount",IF(D18<=40%,"Medium Discount","High Discount"))) -> High Discount
A19: Creative Owl Shape Keychain Black | B19: 199 | C19: 504 | D19: 0.61 | G19: =C19-B19 -> 305 | H19: =IF(F19="","",IF(F19<3,"Poor",IF(F19>=4.5,"Excellent","Average"))) | I19: =IF(D19="","",IF(D19<20%,"Low Discount",IF(D19<=40%,"Medium Discount","High Discount"))) -> High Discount
A20: LASA FOLDING TABLE SERVING STAND | B20: 1274 | C20: 2800 | D20: 0.55 | E20: 5 | F20: 4.8 | G20: =C20-B20 -> 1526 | H20: =IF(F20="","",IF(F20<3,"Poor",IF(F20>=4.5,"Excellent","Average"))) -> Excellent | I20: =IF(D20="","",IF(D20<20%,"Low Discount",IF(D20<=40%,"Medium Discount","High Discount"))) -> High Discount
A21: 5-PCS Stainless Steel Cooking Pot Set With Steamed Slices | B21: 2115 | C21: 4700 | D21: 0.55 | E21: 5 | F21: 2.1 | G21: =C21-B21 -> 2585 | H21: =IF(F21="","",IF(F21<3,"Poor",IF(F21>=4.5,"Excellent","Average"))) -> Poor | I21: =IF(D21="","",IF(D21<20%,"Low Discount",IF(D21<=40%,"Medium Discount","High Discount"))) -> High Discount
A22: Mythco 120COB Solar Wall Ligt With Motion Sensor And Remote Control 3 Modes | B22: 458 | C22: 986 | D22: 0.54 | E22: 10 | F22: 3 | G22: =C22-B22 -> 528 | H22: =IF(F22="","",IF(F22<3,"Poor",IF(F22>=4.5,"Excellent","Average"))) -> Average | I22: =IF(D22="","",IF(D22<20%,"Low Discount",IF(D22<=40%,"Medium Discount","High Discount"))) -> High Discount
A23: LASA 3 Tier Bamboo Shoe Bench Storage Shelf | B23: 2048 | C23: 4500 | D23: 0.54 | E23: 7 | F23: 4.3 | G23: =C23-B23 -> 2452 | H23: =IF(F23="","",IF(F23<3,"Poor",IF(F23>=4.5,"Excellent","Average"))) -> Average | I23: =IF(D23="","",IF(D23<20%,"Low Discount",IF(D23<=40%,"Medium Discount","High Discount"))) -> High Discount
A24: 3PCS Single Head Knitting Crochet Sweater Needle Set | B24: 38 | C24: 80 | D24: 0.53 | E24: 13 | F24: 3.3 | G24: =C24-B24 -> 42 | H24: =IF(F24="","",IF(F24<3,"Poor",IF(F24>=4.5,"Excellent","Average"))) -> Average | I24: =IF(D24="","",IF(D24<20%,"Low Discount",IF(D24<=40%,"Medium Discount","High Discount"))) -> High Discount
A25: Classic Black Cat Cotton Hemp Pillow Case For Home Car | B25: 171 | C25: 360 | D25: 0.53 | E25: 2 | F25: 5 | G25: =C25-B25 -> 189 | H25: =IF(F25="","",IF(F25<3,"Poor",IF(F25>=4.5,"Excellent","Average"))) -> Excellent | I25: =IF(D25="","",IF(D25<20%,"Low Discount",IF(D25<=40%,"Medium Discount","High Discount"))) -> High Discount
A26: Intelligent LED Body Sensor Wireless Lighting Night Light USB | B26: 325 | C26: 680 | D26: 0.52 | E26: 15 | F26: 2.7 | G26: =C26-B26 -> 355 | H26: =IF(F26="","",IF(F26<3,"Poor",IF(F26>=4.5,"Excellent","Average"))) -> Poor | I26: =IF(D26="","",IF(D26<20%,"Low Discount",IF(D26<=40%,"Medium Discount","High Discount"))) -> High Discount
A27: Exfoliate And Exfoliate Face Towel - Black | B27: 185 | C27: 382 | D27: 0.52 | E27: 9 | F27: 4.3 | G27: =C27-B27 -> 197 | H27: =IF(F27="","",IF(F27<3,"Poor",IF(F27>=4.5,"Excellent","Average"))) -> Average | I27: =IF(D27="","",IF(D27<20%,"Low Discount",IF(D27<=40%,"Medium Discount","High Discount"))) -> High Discount
A30: Product | B30: Review | C30: Rating
A31: Classic Black Cat Cotton Hemp Pillow Case For Home Car | B31: 2 | C31: 5
A32: Anti-Skid Absorbent Insulation Coaster For Home Office | B32: 2 | C32: 5
A33: LASA Aluminum Folding Truck Hand Cart - 68kg Max | B33: 3 | C33: 5
A34: Bedroom Simple Floor Hanging Clothes Rack Single Pole Hat Rack - White | B34: 1 | C34: 5
A35: Peacock Throw Pillow Cushion Case For Home Car | B35: 2 | C35: 5
A36: DIY File Folder Office Drawer File Holder Pen Holder Desktop Storage Rack | B36: 1 | C36: 5
A37: Konka Healty Electric Kettle 24-hour Heat Preservation1.5L800W White | B37: 1 | C37: 5
A38: LASA FOLDING TABLE SERVING STAND | B38: 5 | C38: 4.8
A39: 40cm Gold DIY Acrylic Wall Sticker Clock | B39: 12 | C39: 4.8
A40: Portable Home Small Air Humidifier 3-Speed Fan - Green | B40: 5 | C40: 4.8
